input_orders.txt
book
sell 975 90
buy 1299 14
sell 945 51
buy 964 26
buy 757 93
sell 1052 61
sell 1003 34
sell 1244 100
sell 1149 43
sell 893 48
sell 1300 75
buy 924 29
buy 870 93
sell 940 87
buy 1212 21
sell 955 95
sell 897 44
buy 1097 68
buy 1056 40
buy 1074 72
buy 1059 90
buy 1253 94
sell 1034 93
sell 826 23
buy 1126 63
sell 1080 94
sell 1033 95
buy 1211 80
sell 863 79
sell 863 88
buy 831 34
sell 1128 41
buy 754 41
buy 914 66
buy 899 18
buy 1031 80
buy 1022 21
sell 871 80
buy 867 68
sell 791 46
sell 1276 95
sell 752 99
buy 1062 18
buy 1162 71
sell 1032 10
buy 863 76
buy 1086 25
buy 1028 76
sell 1292 97
sell 1203 18
sell 750 15
sell 1093 95
buy 1295 88
sell 1085 56
buy 1244 68
sell 980 95
buy 1227 72
sell 908 16
sell 1293 32
buy 1270 15
sell 962 55
buy 1216 29
sell 1094 25
sell 872 30
buy 866 39
buy 1058 42
buy 793 10
buy 1216 96
buy 785 48
buy 910 74
sell 1000 53
sell 966 63
sell 1245 61
sell 1275 25
buy 1187 14
buy 1257 47
buy 1109 35
buy 966 36
sell 978 83
sell 781 88
buy 1047 69
buy 951 30
sell 1290 100
buy 1151 59
buy 902 49
buy 1039 11
buy 980 48
buy 792 53
sell 1139 85
sell 1207 39
buy 868 25
sell 871 34
buy 919 74
sell 1284 79
buy 965 84
sell 1192 62
buy 862 80
buy 1138 54
sell 868 44
buy 942 89
buy 904 51
buy 813 90
buy 1038 23
buy 1117 10
sell 912 11
sell 1096 26
sell 1160 96
buy 815 42
buy 779 37
sell 752 88
buy 1263 95
buy 899 31
buy 1203 87
sell 1125 41
sell 1122 81
sell 787 99
sell 1201 79
sell 1101 99
buy 911 30
sell 966 34
buy 926 33
buy 1031 15
buy 1160 81
sell 756 57
sell 1276 64
sell 1029 26
buy 1154 86
sell 967 58
sell 1006 86
buy 1080 30
buy 1146 47
buy 1028 28
sell 928 25
sell 1203 90
sell 1291 56
sell 1095 33
buy 1068 34
buy 821 34
buy 994 59
buy 1131 76
sell 1159 66
buy 1225 27
buy 1075 57
sell 888 16
buy 1244 60
sell 1079 92
sell 904 51
sell 1065 90
buy 774 42
buy 848 31
buy 950 58
buy 1282 94
sell 1073 85
sell 855 85
sell 1050 40
sell 1152 99
sell 908 47
sell 844 47
sell 839 88
buy 877 38
buy 910 97
buy 833 38
sell 1268 84
buy 774 70
sell 1262 67
sell 1127 61
buy 1052 44
buy 902 27
buy 790 61
sell 761 39
sell 1195 64
buy 1102 79
buy 890 29
buy 774 29
sell 966 99
sell 1275 76
buy 1140 86
buy 777 76
buy 1236 36
sell 1108 28
buy 973 15
buy 1069 62
buy 1134 88
buy 925 57
sell 1125 36
sell 1115 35
sell 754 42
buy 1249 31
sell 972 64
sell 973 35
buy 1167 91
buy 1268 51
buy 903 92
sell 1120 55
buy 1108 52
sell 843 45
sell 1189 28
sell 1168 14
sell 1030 32
buy 819 82
buy 934 53
buy 928 12
buy 1106 55
buy 798 17
sell 1085 38
sell 945 22
buy 798 80
sell 859 87
sell 1023 97
buy 924 65
buy 1298 78
sell 1239 21
sell 1287 74
sell 1036 57
buy 1000 32
sell 1172 33
sell 786 88
sell 1109 69
buy 1243 68
buy 893 10
buy 1248 26
sell 956 43
sell 1234 12
buy 1077 85
buy 885 66
buy 1299 100
sell 807 42
sell 898 65
buy 887 60
sell 947 84
buy 1021 47
buy 951 56
buy 1187 81
sell 1072 84
sell 890 51
buy 875 79
buy 998 38
sell 927 46
sell 1072 89
sell 824 42
buy 1185 61
buy 1182 100
sell 1057 48
buy 1268 12
buy 893 61
sell 1237 55
buy 760 78
buy 1054 63
sell 798 96
buy 1004 20
buy 1288 27
buy 1289 36
buy 1237 100
buy 1286 19
buy 1293 76
sell 1010 43
buy 955 34
sell 755 20
buy 999 90
sell 926 11
buy 838 50
sell 1294 40
sell 1101 77
sell 837 98
sell 1076 51
buy 1163 91
buy 1205 31
buy 952 76
sell 1289 89
sell 862 79
buy 983 25
buy 945 50
buy 1234 48
buy 885 29
sell 972 46
buy 813 76
buy 996 32
sell 935 29
sell 1005 73
buy 882 35
buy 1189 17
sell 1223 27
sell 966 42
sell 766 36
buy 1073 56
buy 1235 39
sell 874 76
sell 1210 39
sell 1111 46
buy 1264 42
sell 1157 65
buy 1277 30
buy 957 15
buy 1269 73
buy 1241 31
sell 1044 85
buy 1163 86
buy 1231 96
buy 994 80
buy 753 43
buy 981 89
sell 1031 18
sell 948 20
sell 1149 59
buy 1235 64
buy 1013 15
sell 1218 92
buy 1214 20
buy 1127 47
sell 1156 73
sell 1020 82
sell 1149 27
buy 1044 36
sell 788 85
sell 1138 78
sell 1216 54
buy 1165 24
sell 1251 18
buy 1250 97
sell 1158 37
sell 930 63
buy 1100 79
buy 1282 52
sell 1201 49
buy 1238 77
sell 852 90
buy 1174 23
buy 922 37
buy 1293 50
sell 978 17
sell 1124 21
buy 811 40
buy 1284 70
sell 756 70
buy 923 23
buy 763 23
buy 860 67
sell 1182 52
sell 777 48
sell 1055 37
sell 836 19
sell 864 34
sell 1020 91
buy 910 64
buy 1037 73
sell 1181 91
sell 986 94
sell 1038 76
buy 833 83
sell 856 87
sell 801 65
buy 841 15
buy 1283 93
sell 1219 38
buy 766 56
buy 1181 100
sell 1107 20
buy 1261 50
sell 757 13
sell 1141 82
buy 1250 13
sell 1201 31
buy 1265 80
buy 950 65
buy 1024 51
buy 826 99
sell 1210 34
buy 1211 32
sell 787 85
buy 1002 80
buy 1101 65
sell 1262 76
buy 1113 46
buy 1075 45
buy 1051 18
buy 825 99
buy 1128 68
sell 863 82
sell 1257 25
buy 900 100
sell 1099 54
sell 780 10
buy 973 25
buy 945 68
sell 966 58
sell 954 48
sell 1176 19
sell 863 38
sell 848 12
sell 847 84
buy 1033 56
sell 929 77
sell 1235 57
sell 782 12
sell 805 39
buy 773 23
sell 1214 19
buy 1104 62
buy 871 44
buy 855 18
sell 1009 31
sell 854 41
sell 1124 55
sell 1106 28
buy 1016 95
buy 1000 85
buy 954 89
sell 862 18
sell 1210 86
sell 1047 17
buy 790 67
buy 1247 50
buy 1055 54
buy 1086 58
sell 839 26
sell 1043 38
sell 1206 93
sell 1251 73
sell 1272 88
buy 833 39
sell 794 72
buy 1078 13
buy 1224 71
sell 1056 27
buy 769 42
buy 1026 95
sell 1021 84
buy 1017 46
sell 1263 47
buy 976 52
buy 1227 87
buy 960 10
sell 875 78
buy 1182 97
buy 820 32
buy 1065 58
sell 1016 53
buy 1095 64
sell 1242 82
sell 976 79
buy 1013 24
sell 1287 50
sell 1091 91
sell 938 66
sell 944 49
buy 1100 45
buy 989 81
sell 820 66
buy 830 78
sell 849 99
buy 1146 58
sell 1165 11
buy 1291 41
sell 810 34
sell 1190 82
sell 1148 100
sell 959 96
buy 1097 13
buy 1216 29
sell 1127 10
sell 1111 69
buy 844 91
sell 964 38
sell 804 64
sell 991 94
sell 996 63
sell 951 46
buy 1097 95
buy 1046 99
buy 1112 96
sell 1122 75
buy 979 44
buy 1045 76
buy 1098 13
buy 1144 71
buy 1107 41
buy 1022 13
sell 1134 14
buy 1221 99
sell 795 34
buy 835 19
buy 1010 38
buy 865 40
buy 896 82
sell 790 67
buy 986 77
sell 1137 34
buy 1009 71
sell 837 10
sell 929 55
buy 1157 19
buy 1134 81
buy 1072 23
buy 928 41
buy 771 57
buy 978 86
buy 1286 25
buy 1215 59
buy 858 71
buy 1232 90
buy 826 60
buy 913 58
buy 1282 78
buy 960 32
buy 1100 92
sell 835 24
sell 1042 16
sell 1267 60
buy 1044 47
sell 1056 92
sell 940 52
sell 1084 38
buy 954 100
buy 979 25
sell 1250 64
buy 1043 22
sell 769 55
sell 970 27
sell 877 15
sell 917 77
sell 1249 81
buy 1004 61
sell 907 20
buy 911 90
sell 1151 68
sell 1295 43
buy 903 59
sell 894 81
sell 1037 43
buy 872 33
sell 929 10
sell 755 98
buy 905 92
sell 1083 89
sell 1140 45
sell 835 25
sell 872 49
sell 846 32
sell 757 44
buy 1292 51
sell 1036 88
sell 1166 98
sell 1222 65
sell 1171 21
buy 1078 15
sell 1133 19
sell 892 85
buy 1041 86
buy 843 100
buy 850 62
sell 791 96
buy 813 11
buy 1032 39
sell 955 20
buy 992 26
sell 1143 72
sell 847 17
sell 794 17
sell 1155 72
buy 955 13
sell 1077 71
buy 1135 42
sell 1005 74
sell 1158 41
sell 1001 60
sell 923 30
sell 1300 29
sell 1088 27
sell 1061 23
sell 925 28
sell 1108 24
sell 1092 61
buy 1076 88
sell 1289 18
buy 836 69
buy 791 23
sell 778 86
buy 773 95
buy 1112 98
sell 1200 11
sell 1160 44
sell 1116 92
buy 1125 35
sell 1078 72
sell 1061 29
buy 1285 100
sell 809 38
sell 963 83
buy 1073 67
buy 1135 71
sell 1117 64
buy 968 13
sell 1007 39
buy 1028 100
sell 840 21
buy 1020 92
buy 915 77
sell 976 68
buy 804 16
buy 1253 40
sell 872 29
buy 827 99
sell 914 15
sell 934 71
buy 1222 35
sell 1166 90
buy 779 66
sell 925 23
buy 1079 53
sell 1043 88
sell 935 18
sell 1089 92
buy 1140 53
buy 970 69
buy 851 68
sell 1238 14
sell 1079 34
sell 775 34
sell 835 18
sell 1225 30
sell 1098 75
sell 1124 46
buy 1050 11
buy 1213 83
sell 879 90
buy 864 32
sell 969 13
sell 1159 42
buy 979 54
sell 1082 83
sell 985 18
buy 1041 28
sell 1295 100
sell 1177 95
buy 1172 35
buy 1123 80
buy 801 27
buy 1196 66
buy 838 11
buy 827 29
buy 1027 11
buy 1201 28
buy 791 64
buy 1122 25
sell 960 15
buy 892 42
buy 940 79
sell 968 70
sell 888 53
sell 987 55
sell 1193 14
buy 1166 86
buy 1054 12
buy 809 25
buy 755 15
sell 1050 57
buy 1166 34
buy 1278 81
buy 802 54
sell 1067 27
buy 1023 41
sell 1223 47
buy 800 66
